Workbook

Sheet Form responses 1
A1: Timestamp | B1: Name | C1: Whatsapp number | D1: Batting | E1: Bowling | F1: Bowling preference | G1: Rate yourself out of 10. | H1: Food preference | I1: Photo | J1: Any suggestions? | K1: Cricheroes number | L1: Payment | M1: Status | N1: Image | O1: Notes | P1: Total Players Needed | Q1: Paid | R1: Remaining
A2: 46165.555 | B2: Arijit Roy | C2: 7003813326 | D2: Right hand batter | E2: Right arm bowler | F2: Both (bowler cannot switch in the same match) | G2: 8 | H2: Non-veg | I2: https://drive.google.com/open?id=1GYoKt7n9nKtNm3OhdNXXuHfk5K4t1MNR | J2: Na | L2: 500 | M2: =IF(OR(L2=500,L2=800),"Complete","Pending") -> Complete | N2: =IFERROR(__xludf.DUMMYFUNCTION("IMAGE(""https://drive.google.com/uc?export=view&id=""&REGEXEXTRACT(I2,""id=([^&]+)""))"),"") | P2: 40 | Q2: =COUNTIFS(Form_Responses[[#ALL],[Status]],"Complete") -> 31 | R2: =P2-Q2 -> 9
A3: 46165.557 | B3: Aman Jaiswal | C3: 9088787359 | D3: Right hand batter | E3: Right arm bowler | F3: Both (bowler cannot switch in the same match) | G3: 7 | H3: Non-veg | I3: https://drive.google.com/open?id=1MJQ-gAoGTHDsWvMIWkIIia2UQfQZ81tf | J3: I want to participate as a Captain. | L3: 800 | M3: =IF(OR(L3=500,L3=800),"Complete","Pending") -> Complete | N3: =IFERROR(__xludf.DUMMYFUNCTION("IMAGE(""https://drive.google.com/uc?export=view&id=""&REGEXEXTRACT(I3,""id=([^&]+)""))"),"") | P3: Total Collection Required | Q3: Collected | R3: Due
A4: 46165.56 | B4: Sawon Bhattacharya | C4: 8013276482 | D4: Right hand batter | E4: Right arm bowler | F4: Full hand bowling | G4: 7 | H4: Non-veg | I4: https://drive.google.com/open?id=10r8HThmdwZImNTWnOAVBtjXoj0KwwwVc | J4: 14Th June | L4: 800 | M4: =IF(OR(L4=500,L4=800),"Complete","Pending") -> Complete | N4: =IFERROR(__xludf.DUMMYFUNCTION("IMAGE(""https://drive.google.com/uc?export=view&id=""&REGEXEXTRACT(I4,""id=([^&]+)""))"),"") | P4: =(500*36)+(4*800) -> 21200 | Q4: =SUMIFS(Form_Responses[[#ALL],[Payment]],Form_Responses[[#ALL],[Status]],"Complete") -> 16700 | R4: =P4-Q4 -> 4500
A5: 46165.571 | B5: Harshit jaiswal | C5: 7439658397 | D5: Right hand batter | E5: Right arm bowler | F5: Full hand bowling | G5: 7 | H5: Non-veg | I5: https://drive.google.com/open?id=1gtTHY8iXMM8gbEjsYjHhCmvGxeakzoX7 | J5: No | L5: 500 | M5: =IF(OR(L5=500,L5=800),"Complete","Pending") -> Complete | N5: =IFERROR(__xludf.DUMMYFUNCTION("IMAGE(""https://drive.google.com/uc?export=view&id=""&REGEXEXTRACT(I5,""id=([^&]+)""))"),"")
A6: 46165.581 | B6: Spandan Ganguly | C6: 6291007374 | D6: Right hand batter | E6: Right arm bowler | F6: Throw | G6: 5 | H6: Non-veg | I6: https://drive.google.com/open?id=1S55Lf0_wBGR2SQDi56KOtK1pBMxfJMsu | J6: Nothing | M6: =IF(OR(L6=500,L6=800),"Complete","Pending") -> Pending | N6: =IFERROR(__xludf.DUMMYFUNCTION("IMAGE(""https://drive.google.com/uc?export=view&id=""&REGEXEXTRACT(I6,""id=([^&]+)""))"),"")
A7: 46165.609 | B7: Sankar ghosh | C7: 7003378345 | D7: Right hand batter | E7: Right arm bowler | F7: Both (bowler cannot switch in the same match) | G7: 8 | H7: Non-veg | I7: https://drive.google.com/open?id=1Cnu8DJMnlvHWgR4Etqe31cOJYT8_Eawh | J7: No | M7: =IF(OR(L7=500,L7=800),"Complete","Pending") -> Pending | N7: =IFERROR(__xludf.DUMMYFUNCTION("IMAGE(""https://drive.google.com/uc?export=view&id=""&REGEXEXTRACT(I7,""id=([^&]+)""))"),"")
A8: 46165.627 | B8: Arijit Lal | C8: 9547008025 | D8: Right hand batter | E8: Right arm bowler | F8: Both (bowler cannot switch in the same match) | G8: 2 | H8: Non-veg | I8: https://drive.google.com/open?id=1dAQTAno74uagZag5__YHLgAZOpbXS0Yw | L8: 500 | M8: =IF(OR(L8=500,L8=800),"Complete","Pending") -> Complete | N8: =IFERROR(__xludf.DUMMYFUNCTION("IMAGE(""https://drive.google.com/uc?export=view&id=""&REGEXEXTRACT(I8,""id=([^&]+)""))"),"")
A9: 46165.842 | B9: Shantanu Chakroborty | C9: 9088330933 | D9: Right hand batter | E9: Right arm bowler | F9: Both (bowler cannot switch in the same match) | G9: 5 | H9: Non-veg | I9: https://drive.google.com/open?id=1BgSOK86f3Qx_n9R5no2mMg7_RIp4WdnX | M9: =IF(OR(L9=500,L9=800),"Complete","Pending") -> Pending | N9: =IFERROR(__xludf.DUMMYFUNCTION("IMAGE(""https://drive.google.com/uc?export=view&id=""&REGEXEXTRACT(I9,""id=([^&]+)""))"),"")
A10: 46165.919 | B10: BIJON MONDAL | C10: 8584991332 | D10: Right hand batter | E10: Right arm bowler | F10: Full hand bowling | G10: 5 | H10: Non-veg | I10: https://drive.google.com/open?id=18vnmc-ZsBTaPlSJMbDN4EwejSHk5pIaD | L10: 500 | M10: =IF(OR(L10=500,L10=800),"Complete","Pending") -> Complete | N10: =IFERROR(__xludf.DUMMYFUNCTION("IMAGE(""https://drive.google.com/uc?export=view&id=""&REGEXEXTRACT(I10,""id=([^&]+)""))"),"") | O10: Shyambazar Cricheroes
A11: 46165.931 | B11: Ankit Jaiswal | C11: 8100508692 | D11: Right hand batter | E11: Right arm bowler | F11: Throw | G11: 7 | H11: Non-veg | I11: https://drive.google.com/open?id=15H0dsU60tD86x1452Yom6E8R8ZdWWK_r | K11: 8100508692 | M11: =IF(OR(L11=500,L11=800),"Complete","Pending") -> Pending | N11: =IFERROR(__xludf.DUMMYFUNCTION("IMAGE(""https://drive.google.com/uc?export=view&id=""&REGEXEXTRACT(I11,""id=([^&]+)""))"),"")
A12: 46166.101 | B12: Shubham Kumar | C12: 7890403653 | D12: Right hand batter | E12: Right arm bowler | F12: Throw | G12: 3 | H12: Non-veg | I12: https://drive.google.com/open?id=1gbXYoVE_ZCLO-96mCuopgHYqAavcU7Dm | J12: No | K12: 7890403653 | M12: =IF(OR(L12=500,L12=800),"Complete","Pending") -> Pending | N12: =IFERROR(__xludf.DUMMYFUNCTION("IMAGE(""https://drive.google.com/uc?export=view&id=""&REGEXEXTRACT(I12,""id=([^&]+)""))"),"")
A13: 46166.429 | B13: ANIRBAN PAUL | C13: 9123927380 | D13: Right hand batter | E13: Right arm bowler | F13: Throw | G13: 2 | H13: Non-veg | I13: https://drive.google.com/open?id=11icULVIJ75z_uRFxHyNwXan37eabOFkV | K13: 9123927380 | M13: =IF(OR(L13=500,L13=800),"Complete","Pending") -> Pending | N13: =IFERROR(__xludf.DUMMYFUNCTION("IMAGE(""https://drive.google.com/uc?export=view&id=""&REGEXEXTRACT(I13,""id=([^&]+)""))"),"")
A14: 46166.529 | B14: Debashish Roy | C14: 7439065112 | D14: Right hand batter | E14: Right arm bowler | F14: Full hand bowling | G14: 10 | H14: Non-veg | I14: https://drive.google.com/open?id=12FsGW9yMtdQoicmkKV3JzeJrNNlrQcrx | J14: Timely match start karna | K14: 9038044929 | L14: 500 | M14: =IF(OR(L14=500,L14=800),"Complete","Pending") -> Complete | N14: =IFERROR(__xludf.DUMMYFUNCTION("IMAGE(""https://drive.google.com/uc?export=view&id=""&REGEXEXTRACT(I14,""id=([^&]+)""))"),"")
A15: 46166.582 | B15: Swapneel Chakraborty | C15: 9654581813 | D15: Right hand batter | E15: Right arm bowler | F15: Full hand bowling | G15: 10 | H15: Non-veg | I15: https://drive.google.com/open?id=1sfs6iMjc2X7cRm8zRwfi9-8pBg5bNdFc | J15: DRAGLEEOO ko captain mat banao | K15: 8777357716 | L15: 800 | M15: =IF(OR(L15=500,L15=800),"Complete","Pending") -> Complete | N15: =IFERROR(__xludf.DUMMYFUNCTION("IMAGE(""https://drive.google.com/uc?export=view&id=""&REGEXEXTRACT(I15,""id=([^&]+)""))"),"")
A16: 46166.63 | B16: DHRITIMAN DEY | C16: 8224882571 | D16: Right hand batter | E16: Right arm bowler | F16: Both (bowler cannot switch in the same match) | G16: 10 | H16: Non-veg | I16: https://drive.google.com/open?id=1P2VyQ05qff0qu96psQqBd9snNGdLwCyF | K16: 8224882571 | L16: 500 | M16: =IF(OR(L16=500,L16=800),"Complete","Pending") -> Complete | N16: =IFERROR(__xludf.DUMMYFUNCTION("IMAGE(""https://drive.google.com/uc?export=view&id=""&REGEXEXTRACT(I16,""id=([^&]+)""))"),"") | O16: Bijan Mondal Reference
A17: 46166.949 | B17: Rahul Sen | C17: 9088126567 | D17: Right hand batter | E17: Right arm bowler | F17: Throw | G17: 7 | H17: Non-veg | I17: https://drive.google.com/open?id=11Q6C_SPO0Y7GG-dWOeNS9F9pJga_mtWH | J17: NA | K17: 9088126567 | M17: =IF(OR(L17=500,L17=800),"Complete","Pending") -> Pending | N17: =IFERROR(__xludf.DUMMYFUNCTION("IMAGE(""https://drive.google.com/uc?export=view&id=""&REGEXEXTRACT(I17,""id=([^&]+)""))"),"") | O17: Mukundpur Cricheroes
A18: 46166.982 | B18: ROHIT GHOSH (BABAI) | C18: 8585808364 | D18: Right hand batter | E18: Right arm bowler | F18: Both (bowler cannot switch in the same match) | G18: 5 | H18: Non-veg | I18: https://drive.google.com/open?id=1Lutb7jiS17qfv2Tsiej4xtj-fIVtwIRl | K18: 8585808364 | L18: 500 | M18: =IF(OR(L18=500,L18=800),"Complete","Pending") -> Complete | N18: =IFERROR(__xludf.DUMMYFUNCTION("IMAGE(""https://drive.google.com/uc?export=view&id=""&REGEXEXTRACT(I18,""id=([^&]+)""))"),"") | O18: Bijan Mondal Reference
A19: 46167.78 | B19: Ujjawal Kumar Jha | C19: 6290270377 | D19: Right hand batter | E19: Right arm bowler | F19: Both (bowler cannot switch in the same match) | G19: 1 | H19: Non-veg | I19: https://drive.google.com/open?id=1-4buFuqZdLECpbwTxpmhJjYUTdHVtdxY | J19: Dragleeoo gandu hai | K19: 6290270377 | L19: 500 | M19: =IF(OR(L19=500,L19=800),"Complete","Pending") -> Complete | N19: =IFERROR(__xludf.DUMMYFUNCTION("IMAGE(""https://drive.google.com/uc?export=view&id=""&REGEXEXTRACT(I19,""id=([^&]+)""))"),"")
A20: 46167.79 | B20: Jewel Johnson | C20: 8981470319 | D20: Right hand batter | E20: Right arm bowler | F20: Both (bowler cannot switch in the same match) | G20: 6 | H20: Non-veg | I20: https://drive.google.com/open?id=129XbrfkwcRmRRyONOhFZmIFX53OPiP87 | K20: 8981470319 | L20: 500 | M20: =IF(OR(L20=500,L20=800),"Complete","Pending") -> Complete | N20: =IFERROR(__xludf.DUMMYFUNCTION("IMAGE(""https://drive.google.com/uc?export=view&id=""&REGEXEXTRACT(I20,""id=([^&]+)""))"),"") | O20: 500 paid for sunil as well
A21: 46167.806 | B21: Abhishek Sarkar | C21: 7980721344 | D21: Right hand batter | E21: Right arm bowler | F21: Both (bowler cannot switch in the same match) | G21: 8 | H21: Non-veg | I21: https://drive.google.com/open?id=19ebheC2JW1zaQqTSlkraqwykHXEZxt7A | J21: Dont make me marquee , just an average player with average stats…. | K21: 7980721344 | L21: 500 | M21: =IF(OR(L21=500,L21=800),"Complete","Pending") -> Complete | N21: =IFERROR(__xludf.DUMMYFUNCTION("IMAGE(""https://drive.google.com/uc?export=view&id=""&REGEXEXTRACT(I21,""id=([^&]+)""))"),"")
A22: 46167.826 | B22: AMD | C22: 8777353249 | D22: Right hand batter | E22: Right arm bowler | F22: Full hand bowling | G22: 5 | H22: Non-veg | I22: https://drive.google.com/open?id=1Q11XoRvhipc1zUxfgcmdqCQI4Jd4hfz- | J22: Umpire bahar se mangwao | K22: 8777353249 | L22: 800 | M22: =IF(OR(L22=500,L22=800),"Complete","Pending") -> Complete | N22: =IFERROR(__xludf.DUMMYFUNCTION("IMAGE(""https://drive.google.com/uc?export=view&id=""&REGEXEXTRACT(I22,""id=([^&]+)""))"),"")
A23: 46167.889 | B23: Subhashis Das | C23: 6290007449 | D23: Right hand batter | E23: Right arm bowler | F23: Both (bowler cannot switch in the same match) | G23: 10 | H23: Non-veg | I23: https://drive.google.com/open?id=10qKFotFiwS5UqDKhhzsvQ8BtlV51QgQa | J23: Pls arrange the tournament in a neutral way... | K23: 6290007449 | L23: 500 | M23: =IF(OR(L23=500,L23=800),"Complete","Pending") -> Complete | N23: =IFERROR(__xludf.DUMMYFUNCTION("IMAGE(""https://drive.google.com/uc?export=view&id=""&REGEXEXTRACT(I23,""id=([^&]+)""))"),"")
A24: 46168.017 | B24: Soumyojit Bhattacharjee | C24: 9038189636 | D24: Right hand batter | E24: Right arm bowler | F24: Throw | G24: 6 | H24: Non-veg | I24: https://drive.google.com/open?id=1qbKs-ZeD03Nwv3FSbK6MMa9mzmmtEYHl | K24: 8910941319 | M24: =IF(OR(L24=500,L24=800),"Complete","Pending") -> Pending | N24: =IFERROR(__xludf.DUMMYFUNCTION("IMAGE(""https://drive.google.com/uc?export=view&id=""&REGEXEXTRACT(I24,""id=([^&]+)""))"),"")
A25: 46168.019 | B25: Jit | C25: 7003662153 | D25: Right hand batter | E25: Right arm bowler | F25: Throw | G25: 10 | H25: Non-veg | I25: https://drive.google.com/open?id=1bSmtQ9vXLAKophQ54vd0coijkdmBT4VH | J25: ONE WORD, DON | K25: 7003662153 | L25: 500 | M25: =IF(OR(L25=500,L25=800),"Complete","Pending") -> Complete | N25: =IFERROR(__xludf.DUMMYFUNCTION("IMAGE(""https://drive.google.com/uc?export=view&id=""&REGEXEXTRACT(I25,""id=([^&]+)""))"),"")
A26: 46168.364 | B26: Indronil Das | C26: 8583808935 | D26: Right hand batter | E26: Right arm bowler | F26: Both (bowler cannot switch in the same match) | G26: 6 | H26: Non-veg | I26: https://drive.google.com/open?id=1CYxgIgrKe3s3nNU_yy4EWbZGXnDjk-pR | K26: 8583808935 | L26: 500 | M26: =IF(OR(L26=500,L26=800),"Complete","Pending") -> Complete | N26: =IFERROR(__xludf.DUMMYFUNCTION("IMAGE(""https://drive.google.com/uc?export=view&id=""&REGEXEXTRACT(I26,""id=([^&]+)""))"),"")
A27: 46172.431 | B27: Avi Sengupta | C27: 8981936020 | D27: Right hand batter | E27: Right arm bowler | F27: Full hand bowling | G27: 8 | H27: Non-veg | I27: https://drive.google.com/open?id=1zwfKDnn8gBlmAOhZ-YBzs8PH6rh0wA3m | J27: Na | K27: 8981936020 | L27: 500 | M27: =IF(OR(L27=500,L27=800),"Complete","Pending") -> Complete | N27: =IFERROR(__xludf.DUMMYFUNCTION("IMAGE(""https://drive.google.com/uc?export=view&id=""&REGEXEXTRACT(I27,""id=([^&]+)""))"),"")
A28: 46172.439 | B28: Abhijeet Pal | C28: 9144868713 | D28: Right hand batter | E28: Right arm bowler | F28: Full hand bowling | G28: 9 | H28: Non-veg | I28: https://drive.google.com/open?id=1tW4k45_c9TCxasT6z7xSssouttWar80Q | J28: NA | K28: 9144868713 | L28: 500 | M28: =IF(OR(L28=500,L28=800),"Complete","Pending") -> Complete | N28: =IFERROR(__xludf.DUMMYFUNCTION("IMAGE(""https://drive.google.com/uc?export=view&id=""&REGEXEXTRACT(I28,""id=([^&]+)""))"),"")
A29: 46172.557 | B29: Samir | C29: 7003388162 | D29: Right hand batter | E29: Right arm bowler | F29: Throw | G29: 1 | H29: Veg | I29: https://drive.google.com/open?id=1rgsGFEHqAQc_J_ns3uW5NSO-_tMUpd0k | K29: 7003388162 | L29: 500 | M29: =IF(OR(L29=500,L29=800),"Complete","Pending") -> Complete | N29: =IFERROR(__xludf.DUMMYFUNCTION("IMAGE(""https://drive.google.com/uc?export=view&id=""&REGEXEXTRACT(I29,""id=([^&]+)""))"),"")
A30: 46172.812 | B30: Arijit Kundu | C30: 7003347354 | D30: Right hand batter | E30: Right arm bowler | F30: Full hand bowling | G30: 1 | H30: Non-veg | I30: https://drive.google.com/open?id=1-Cj8OxDmwEyvEDKvEtFOPT6JtoSD5X1c | K30: 7003347354 | L30: 500 | M30: =IF(OR(L30=500,L30=800),"Complete","Pending") -> Complete | N30: =IFERROR(__xludf.DUMMYFUNCTION("IMAGE(""https://drive.google.com/uc?export=view&id=""&REGEXEXTRACT(I30,""id=([^&]+)""))"),"")
A31: 46174.564 | B31: Prince | C31: 8478875174 | D31: Right hand batter | E31: Right arm bowler | F31: Both (bowler cannot switch in the same match) | G31: 7 | H31: Non-veg | I31: https://drive.google.com/open?id=1EnwmuOoVIY-kqAKVzm9k7m6E7E-rdXKc | K31: 8478875174 | L31: 500 | M31: =IF(OR(L31=500,L31=800),"Complete","Pending") -> Complete | N31: =IFERROR(__xludf.DUMMYFUNCTION("IMAGE(""https://drive.google.com/uc?export=view&id=""&REGEXEXTRACT(I31,""id=([^&]+)""))"),"")
A32: 46174.585 | B32: Anirban Guha | C32: 8670063670 | D32: Right hand batter | E32: Right arm bowler | F32: Throw | G32: 6 | H32: Non-veg | I32: https://drive.google.com/open?id=1awGd8GDpFClofR3birw2PDQK2Fhe7B4b | J32: I am Dinda ka brother | K32: 8670063670 | L32: 500 | M32: =IF(OR(L32=500,L32=800),"Complete","Pending") -> Complete | N32: =IFERROR(__xludf.DUMMYFUNCTION("IMAGE(""https://drive.google.com/uc?export=view&id=""&REGEXEXTRACT(I32,""id=([^&]+)""))"),"")
A33: 46175.008 | B33: sen | C33: 9330693101 | D33: Left hand batter | E33: Right arm bowler | F33: Throw | G33: 2 | H33: Non-veg | I33: https://drive.google.com/open?id=1jB2WItO5eJHGWn7P1BeuiqZW3U1q8s4C | J33: NA | K33: 9330693101 | L33: 500 | M33: =IF(OR(L33=500,L33=800),"Complete","Pending") -> Complete | N33: =IFERROR(__xludf.DUMMYFUNCTION("IMAGE(""https://drive.google.com/uc?export=view&id=""&REGEXEXTRACT(I33,""id=([^&]+)""))"),"")
A34: 46175.871 | B34: Salman | C34: 9836867702 | D34: Right hand batter | E34: Right arm bowler | F34: Full hand bowling | G34: 7 | H34: Non-veg | I34: https://drive.google.com/open?id=1CqczhtEOxvY0N0tHEchVBcjq7pA1fTH- | K34: 9836867702 | M34: =IF(OR(L34=500,L34=800),"Complete","Pending") -> Pending | N34: =IFERROR(__xludf.DUMMYFUNCTION("IMAGE(""https://drive.google.com/uc?export=view&id=""&REGEXEXTRACT(I34,""id=([^&]+)""))"),"")
A35: 46175.934 | B35: Harshit Agarwal | C35: 9330279692 | D35: Right hand batter | E35: Right arm bowler | F35: Full hand bowling | G35: 6 | H35: Non-veg | I35: https://drive.google.com/open?id=1RUH7ZbPL86dpcA_0-ZQg4v_tPSQQ3sQm | J35: Good umpires, on time matches. | K35: 9330279692 | M35: =IF(OR(L35=500,L35=800),"Complete","Pending") -> Pending | N35: =IFERROR(__xludf.DUMMYFUNCTION("IMAGE(""https://drive.google.com/uc?export=view&id=""&REGEXEXTRACT(I35,""id=([^&]+)""))"),"")
A36: 46175.962 | B36: BALARAM | C36: 9674773735 | D36: Right hand batter | E36: Right arm bowler | F36: Full hand bowling | G36: 8 | H36: Non-veg | I36: https://drive.google.com/open?id=1m8t-2V_7Ik2Mv5HsqT91qldMVeP2i2Cz | K36: 9674773735 | L36: 500 | M36: =IF(OR(L36=500,L36=800),"Complete","Pending") -> Complete | N36: =IFERROR(__xludf.DUMMYFUNCTION("IMAGE(""https://drive.google.com/uc?export=view&id=""&REGEXEXTRACT(I36,""id=([^&]+)""))"),"")
A37: 46176.845 | B37: Ananya Roy | C37: 8910827445 | D37: Right hand batter | E37: Right arm bowler | F37: Throw | G37: 6 | H37: Non-veg | I37: https://drive.google.com/open?id=1sJW_sFmI8vRtf-E2ErdFZ-mE6L9dhbZD | K37: 8910827445 | M37: =IF(OR(L37=500,L37=800),"Complete","Pending") -> Pending | N37: =IFERROR(__xludf.DUMMYFUNCTION("IMAGE(""https://drive.google.com/uc?export=view&id=""&REGEXEXTRACT(I37,""id=([^&]+)""))"),"")
A38: 46177.436 | B38: Tias Chatterjee | C38: 6290441191 | D38: Left hand batter | E38: Left arm bowler | F38: Throw | G38: 6 | H38: Non-veg | I38: https://drive.google.com/open?id=1Sv_Do71B3f9IdUi1xhO9TNxlPFQOPAA2 | K38: 6290441191 | L38: 500 | M38: =IF(OR(L38=500,L38=800),"Complete","Pending") -> Complete | N38: =IFERROR(__xludf.DUMMYFUNCTION("IMAGE(""https://drive.google.com/uc?export=view&id=""&REGEXEXTRACT(I38,""id=([^&]+)""))"),"")
A39: 46177.472 | B39: Joy Mitra | C39: 7980806314 | D39: Right hand batter | E39: Right arm bowler | F39: Throw | G39: 5 | H39: Non-veg | I39: https://drive.google.com/open?id=16CSglA5xxp4jGjGdLhUxhimkAXOWjhRo | K39: 7980806314 | L39: 500 | M39: =IF(OR(L39=500,L39=800),"Complete","Pending") -> Complete | N39: =IFERROR(__xludf.DUMMYFUNCTION("IMAGE(""https://drive.google.com/uc?export=view&id=""&REGEXEXTRACT(I39,""id=([^&]+)""))"),"")
A40: 46177.739 | B40: Tushal | C40: 7980012825 | D40: Right hand batter | E40: Right arm bowler | F40: Throw | G40: 7 | H40: Non-veg | I40: https://drive.google.com/open?id=1AkMy_Nk300OBbl7VM1XvLM0YnONA9klB | K40: 7980012825 | M40: =IF(OR(L40=500,L40=800),"Complete","Pending") -> Pending | N40: =IFERROR(__xludf.DUMMYFUNCTION("IMAGE(""https://drive.google.com/uc?export=view&id=""&REGEXEXTRACT(I40,""id=([^&]+)""))"),"")
...

Sheet Player_DB
A1: Player ID | B1: Name | C1: Matches | D1: Innings | E1: Runs | F1: Avg | G1: SR | H1: Best Score | I1: Wickets | J1: Economy | K1: Fielding Dismissals | L1: Profile
A2: 33918878 | B2: ANIRBAN PAUL | C2: 16 | D2: 12 | E2: 162 | F2: 16.2 | G2: 186.21 | H2: 34* | I2: 4 | J2: 14.5 | K2: 13 | L2: =HYPERLINK("https://cricheroes.com/player-profile/33918878/anirban-paul/stats","View Profile") -> View Profile
A3: 19685723 | B3: Arijit roy | C3: 110 | D3: 73 | E3: 589 | F3: 11.33 | G3: 131.77 | H3: 37 | I3: 47 | J3: 12.22 | K3: 22 | L3: =HYPERLINK("https://cricheroes.com/player-profile/19685723/arijit-roy/stats","View Profile") -> View Profile
A4: 11374748 | B4: HARSHIT JAISWAL | C4: 46 | D4: 36 | E4: 725 | F4: 30.21 | G4: 183.54 | H4: 52 | I4: 21 | J4: 8.98 | K4: 36 | L4: =HYPERLINK("https://cricheroes.com/player-profile/11374748/harshit-jaiswal/stats","View Profile") -> View Profile
A5: 28643694 | B5: Pritam Basu | C5: 86 | D5: 73 | E5: 715 | F5: 12.12 | G5: 136.45 | H5: 60 | I5: 44 | J5: 8.8 | K5: 35 | L5: =HYPERLINK("https://cricheroes.com/player-profile/28643694/pritam-basu/stats","View Profile") -> View Profile
A6: 14374771 | B6: Spandan Ganguly | C6: 154 | D6: 55 | E6: 176 | F6: 4.89 | G6: 86.7 | H6: 26* | I6: 23 | J6: 9.97 | K6: 33 | L6: =HYPERLINK("https://cricheroes.com/player-profile/14374771/spandan-ganguly/stats","View Profile") -> View Profile
A7: 29077191 | B7: Fardeen ali | C7: 222 | D7: 178 | E7: 1471 | F7: 10.29 | G7: 93.34 | H7: 60 | I7: 142 | J7: 5.62 | K7: 89 | L7: =HYPERLINK("https://cricheroes.com/player-profile/29077191/fardeen-ali/stats","View Profile") -> View Profile
A8: 46477829 | B8: Sankar Ghosh | C8: 24 | D8: 12 | E8: 117 | F8: 14.63 | G8: 156 | H8: 45 | I8: 12 | J8: 10.22 | K8: 10 | L8: =HYPERLINK("https://cricheroes.com/player-profile/46477829/sankar-ghosh/stats","View Profile") -> View Profile
A9: 43016896 | B9: Arijit | C9: 63 | D9: 42 | E9: 488 | F9: 14.35 | G9: 162.67 | H9: 50* | I9: 35 | J9: 7.92 | K9: 35 | L9: =HYPERLINK("https://cricheroes.com/player-profile/43016896/arijit/stats","View Profile") -> View Profile
A10: 11616298 | B10: Shantanu Chakraborty | C10: 21 | D10: 7 | E10: 36 | F10: 18 | G10: 120 | H10: 10* | I10: 8 | J10: 9.34 | K10: 6 | L10: =HYPERLINK("https://cricheroes.com/player-profile/11616298/shantanu-chakraborty/stats","View Profile") -> View Profile
A11: 37888165 | B11: Bijon Mondal | C11: 105 | D11: 76 | E11: 865 | F11: 17.65 | G11: 191.37 | H11: 94* | I11: 39 | J11: 11.6 | K11: 61 | L11: =HYPERLINK("https://cricheroes.com/player-profile/37888165/bijon-mondal/stats","View Profile") -> View Profile
A12: 11077697 | B12: Ankit Jaiswal | C12: 46 | D12: 40 | E12: 507 | F12: 18.78 | G12: 169 | H12: 60 | I12: 20 | J12: 9.29 | K12: 25 | L12: =HYPERLINK("https://cricheroes.com/player-profile/11077697/ankit-jaiswal/stats","View Profile") -> View Profile
A13: 33758093 | B13: Shubham Kumar | C13: 15 | D13: 11 | E13: 184 | F13: 26.29 | G13: 213.95 | H13: 41 | I13: 5 | J13: 15.12 | K13: 11 | L13: =HYPERLINK("https://cricheroes.com/player-profile/33758093/shubham-kumar/stats","View Profile") -> View Profile
A14: 3371745 | B14: Debashish Roy | C14: 107 | D14: 89 | E14: 1711 | F14: 21.12 | G14: 131.21 | H14: 105 | I14: 117 | J14: 8.88 | K14: 38 | L14: =HYPERLINK("https://cricheroes.com/player-profile/3371745/debashish-roy/stats","View Profile") -> View Profile
A15: 24512366 | B15: Swapneel Chakraborty | C15: 47 | D15: 38 | E15: 439 | F15: 15.14 | G15: 181.4 | H15: 51 | I15: 25 | J15: 12.77 | K15: 16 | L15: =HYPERLINK("https://cricheroes.com/player-profile/24512366/swapneel-chakraborty/stats","View Profile") -> View Profile
A16: 38392651 | B16: Dhritiman Dey | C16: 79 | D16: 54 | E16: 623 | F16: 19.47 | G16: 171.63 | H16: 48* | I16: 28 | J16: 10.25 | K16: 31 | L16: =HYPERLINK("https://cricheroes.com/player-profile/38392651/dhritiman-dey/stats","View Profile") -> View Profile
A17: 45002297 | B17: Rahul | C17: 14 | D17: 11 | E17: 110 | F17: 18.33 | G17: 142.86 | H17: 24* | I17: 13 | J17: 8.73 | K17: 6 | L17: =HYPERLINK("https://cricheroes.com/player-profile/45002297/rahul/stats","View Profile") -> View Profile
A18: 36055152 | B18: Rohit Ghosh | C18: 73 | D18: 50 | E18: 401 | F18: 10.84 | G18: 131.48 | H18: 38* | I18: 25 | J18: 12.68 | K18: 36 | L18: =HYPERLINK("https://cricheroes.com/player-profile/36055152/rohit-ghosh/stats","View Profile") -> View Profile
A19: 30299329 | B19: Kuntal Das | C19: 69 | D19: 27 | E19: 76 | F19: 3.8 | G19: 86.36 | H19: 20 | I19: 9 | J19: 14.69 | K19: 7 | L19: =HYPERLINK("https://cricheroes.com/player-profile/30299329/kuntal-das/stats","View Profile") -> View Profile
A20: 10984519 | B20: Ujjawal Jha | C20: 187 | D20: 152 | E20: 3072 | F20: 29.26 | G20: 213.63 | H20: 83* | I20: 105 | J20: 9.05 | K20: 127 | L20: =HYPERLINK("https://cricheroes.com/player-profile/10984519/ujjawal-jha/stats","View Profile") -> View Profile
A21: 48762345 | B21: Jewel Johnson | C21: 9 | D21: 8 | E21: 144 | F21: 18 | G21: 211.76 | H21: 35 | I21: 5 | J21: 11.6 | K21: 8 | L21: =HYPERLINK("https://cricheroes.com/player-profile/48762345/jewel-johnson/stats","View Profile") -> View Profile
A22: 12060387 | B22: Abhishek sarkar | C22: 140 | D22: 120 | E22: 1874 | F22: 22.58 | G22: 172.08 | H22: 74* | I22: 82 | J22: 9.89 | K22: 93 | L22: =HYPERLINK("https://cricheroes.com/player-profile/12060387/abhishek-sarkar/stats","View Profile") -> View Profile
A23: 23646088 | B23: DRAGLEEOO | C23: 94 | D23: 83 | E23: 1295 | F23: 18.77 | G23: 189.6 | H23: 114* | I23: 30 | J23: 12.57 | K23: 44 | L23: =HYPERLINK("https://cricheroes.com/player-profile/23646088/dragleeoo/stats","View Profile") -> View Profile
A24: 4779842 | B24: Subhasish Das | C24: 154 | D24: 131 | E24: 2294 | F24: 22.71 | G24: 183.08 | H24: 87* | I24: 59 | J24: 10.5 | K24: 46 | L24: =HYPERLINK("https://cricheroes.com/player-profile/4779842/subhasish-das/stats","View Profile") -> View Profile
A25: 4258050 | B25: Jit | C25: 204 | D25: 172 | E25: 1721 | F25: 12.56 | G25: 148.36 | H25: 65* | I25: 110 | J25: 10.38 | K25: 63 | L25: =HYPERLINK("https://cricheroes.com/player-profile/4258050/jit/stats","View Profile") -> View Profile
A26: 10984703 | B26: Aman Jaiswal | C26: 48 | D26: 40 | E26: 498 | F26: 16.06 | G26: 172.92 | H26: 39* | I26: 26 | J26: 11.25 | K26: 15 | L26: =HYPERLINK("https://cricheroes.com/player-profile/10984703/aman-jaiswal/stats","View Profile") -> View Profile
A27: 10967531 | B27: Sawon Bhattacharya | C27: 79 | D27: 59 | E27: 1028 | F27: 23.91 | G27: 179.72 | H27: 55* | I27: 28 | J27: 11.31 | K27: 37 | L27: =HYPERLINK("https://cricheroes.com/player-profile/10967531/sawon-bhattacharya/stats","View Profile") -> View Profile
A28: 49414345 | B28: Indronil Das | C28: 9 | D28: 6 | E28: 85 | F28: 17 | G28: 151.79 | H28: 39 | I28: 3 | J28: 11.33 | K28: 2 | L28: =HYPERLINK("https://cricheroes.com/player-profile/49414345/indronil-das/stats","View Profile") -> View Profile
A29: 44521368 | B29: Avi sengupta | K29: 0 | L29: =HYPERLINK("https://cricheroes.com/player-profile/44521368/avi-sengupta/stats","View Profile") -> View Profile
A30: 12060554 | B30: Bony | C30: 136 | D30: 106 | E30: 971 | F30: 12.14 | G30: 161.3 | H30: 65 | I30: 48 | J30: 10.46 | K30: 75 | L30: =HYPERLINK("https://cricheroes.com/player-profile/12060554/bony/stats","View Profile") -> View Profile
A31: 40256787 | B31: Avijit Pal Cricket Bhojerhat | C31: 9 | D31: 4 | E31: 38 | F31: 9.5 | G31: 165.22 | H31: 21 | I31: 2 | J31: 11.29 | K31: 2 | L31: =HYPERLINK("https://cricheroes.com/player-profile/40256787/avijit-pal-cricket-bhojerhat/stats","View Profile") -> View Profile
A32: 42598564 | B32: Prince | C32: 126 | D32: 104 | E32: 1539 | F32: 19.48 | G32: 191.18 | H32: 76* | I32: 48 | J32: 11.89 | K32: 58 | L32: =HYPERLINK("https://cricheroes.com/player-profile/42598564/prince/stats","View Profile") -> View Profile
A33: 42627107 | B33: Anirban Guha | C33: 123 | D33: 54 | E33: 375 | F33: 10.14 | G33: 120.97 | H33: 49 | I33: 60 | J33: 10.81 | K33: 36 | L33: =HYPERLINK("https://cricheroes.com/player-profile/42627107/anirban-guha/stats","View Profile") -> View Profile
A34: 47133527 | B34: Sen | C34: 72 | D34: 48 | E34: 648 | F34: 16.62 | G34: 165.73 | H34: 54 | I34: 33 | J34: 10.08 | K34: 29 | L34: =HYPERLINK("https://cricheroes.com/player-profile/47133527/sen/stats","View Profile") -> View Profile
A35: 44011252 | B35: Salman | C35: 55 | D35: 37 | E35: 732 | F35: 27.11 | G35: 196.77 | H35: 61* | I35: 12 | J35: 11.04 | K35: 17 | L35: =HYPERLINK("https://cricheroes.com/player-profile/44011252/salman/stats","View Profile") -> View Profile
A36: 2320856 | B36: Balaram Shil | C36: 648 | D36: 433 | E36: 6590 | F36: 21.61 | G36: 193.77 | H36: 88 | I36: 575 | J36: 11.88 | K36: 394 | L36: =HYPERLINK("https://cricheroes.com/player-profile/2320856/balaram-shil/stats","View Profile") -> View Profile
A37: 21857884 | B37: Harshit | C37: 79 | D37: 60 | E37: 858 | F37: 17.16 | G37: 186.93 | H37: 102 | I37: 10 | J37: 14.33 | K37: 38 | L37: =HYPERLINK("https://cricheroes.com/player-profile/21857884/harshit/stats","View Profile") -> View Profile
A38: 34507530 | B38: Ananya roy | C38: 161 | D38: 93 | E38: 692 | F38: 11.16 | G38: 150.11 | H38: 39* | I38: 56 | J38: 11.82 | K38: 35 | L38: =HYPERLINK("https://cricheroes.com/player-profile/34507530/ananya-roy/stats","View Profile") -> View Profile
A39: 29988182 | B39: Tushal Shaw | C39: 46 | D39: 36 | E39: 463 | F39: 15.43 | G39: 159.11 | H39: 41 | I39: 13 | J39: 10.68 | K39: 26 | L39: =HYPERLINK("https://cricheroes.com/player-profile/29988182/tushal-shaw/stats","View Profile") -> View Profile
A40: 12060748 | B40: Joy Mitra | C40: 110 | D40: 61 | E40: 372 | F40: 9.07 | G40: 134.78 | H40: 30 | I40: 43 | J40: 10.77 | K40: 33 | L40: =HYPERLINK("https://cricheroes.com/player-profile/12060748/joy-mitra/stats","View Profile") -> View Profile
...

Sheet WheelSheet
F2: =IFERROR(VLOOKUP($B$6,'Form responses 1'!$B$1:$N$118,13,FALSE),"")
E3: =IFERROR(VLOOKUP($I$17,'Player Info'!$B:$J,9,0),"")
A5: Name | B5: Unsold
A6: Arijit Roy | B6: Sankar ghosh
A7: Aman Jaiswal
A8: Sawon Bhattacharya | B8: Gaurav Chaudhary
A9: Harshit jaiswal
A10: Pritam Basu
A11: Spandan Ganguly
A13: Sankar ghosh
A14: Arijit Lal
A15: Shantanu Chakroborty
A16: BIJON MONDAL
A18: Shubham Kumar
A19: ANIRBAN PAUL | F19: =IFERROR(UPPER($B$6),"") -> SANKAR GHOSH
A20: Debashish Roy
A21: Swapneel Chakraborty | F21: Base Point | G21: =IFERROR(VLOOKUP($F$19, 'Player Info'!$B:$J,2,0),"")
A22: DHRITIMAN DEY | F22: Batting | G22: =IFERROR(VLOOKUP($F$19, 'Player Info'!$B:$J,3,0),"")
A23: Rahul Sem | F23: Bowling | G23: =IFERROR(VLOOKUP($F$19, 'Player Info'!$B:$J,4,0),"")
A24: ROHIT GHOSH (BABAI) | F24: Full/ Throw | G24: =IFERROR(VLOOKUP($F$19, 'Player Info'!$B:$J,5,0),"")
A25: Kuntal das
A26: Ujjawal Kumar Jha
A27: Jewel Johnson
A28: Abhishek Sarkar
A29: AMD
A30: Subhashis Das
